Workbook

Sheet Menu Profitability
A1: Arepas House - Menu Profitability
A2: Prices from Square catalog (Jul 2026). Costs roll up from the Recipes sheet - edit portions there and this sheet recalculates.
A4: Menu Item | B4: Category | C4: Menu Price | D4: Ingredient Cost | E4: Gross Profit $ | F4: Food Cost % | G4: Margin % | H4: Notes
A5: Yucca Fries (7 units) | B5: Appetizers | C5: 6.99 | D5: =SUMIF(Recipes!$A:$A,$A5,Recipes!$F:$F) | E5: =C5-D5 | F5: =IF(C5=0,"",D5/C5) | G5: =IF(C5=0,"",E5/C5) | H5: INCOMPLETE - yuca price missing (unreadable invoice)
A6: Plantains and Cheese (7 units) | B6: Appetizers | C6: 6.99 | D6: =SUMIF(Recipes!$A:$A,$A6,Recipes!$F:$F) | E6: =C6-D6 | F6: =IF(C6=0,"",D6/C6) | G6: =IF(C6=0,"",E6/C6) | H6: INCOMPLETE - plantain price missing (unreadable invoice)
A7: Tequeños (5 units) | B7: Appetizers | C7: 8.99 | D7: =SUMIF(Recipes!$A:$A,$A7,Recipes!$F:$F) | E7: =C7-D7 | F7: =IF(C7=0,"",D7/C7) | G7: =IF(C7=0,"",E7/C7)
A8: Empanadas | B8: Appetizers | C8: 4.95 | D8: =SUMIF(Recipes!$A:$A,$A8,Recipes!$F:$F) | E8: =C8-D8 | F8: =IF(C8=0,"",D8/C8) | G8: =IF(C8=0,"",E8/C8)
A9: Pastelitos | B9: Appetizers | C9: 4.95 | D9: =SUMIF(Recipes!$A:$A,$A9,Recipes!$F:$F) | E9: =C9-D9 | F9: =IF(C9=0,"",D9/C9) | G9: =IF(C9=0,"",E9/C9)
A10: Arepa Cheese | B10: Arepas | C10: 6.99 | D10: =SUMIF(Recipes!$A:$A,$A10,Recipes!$F:$F) | E10: =C10-D10 | F10: =IF(C10=0,"",D10/C10) | G10: =IF(C10=0,"",E10/C10)
A11: Arepa Domino | B11: Arepas | C11: 6.99 | D11: =SUMIF(Recipes!$A:$A,$A11,Recipes!$F:$F) | E11: =C11-D11 | F11: =IF(C11=0,"",D11/C11) | G11: =IF(C11=0,"",E11/C11)
A12: Arepa Chicken | B12: Arepas | C12: 12.99 | D12: =SUMIF(Recipes!$A:$A,$A12,Recipes!$F:$F) | E12: =C12-D12 | F12: =IF(C12=0,"",D12/C12) | G12: =IF(C12=0,"",E12/C12)
A13: Arepa Pabellon | B13: Arepas | C13: 13.99 | D13: =SUMIF(Recipes!$A:$A,$A13,Recipes!$F:$F) | E13: =C13-D13 | F13: =IF(C13=0,"",D13/C13) | G13: =IF(C13=0,"",E13/C13)
A14: Arepas Vegetarian | B14: Arepas | C14: 10.99 | D14: =SUMIF(Recipes!$A:$A,$A14,Recipes!$F:$F) | E14: =C14-D14 | F14: =IF(C14=0,"",D14/C14) | G14: =IF(C14=0,"",E14/C14)
A15: Arepa Vegan | B15: Arepas | C15: 10.99 | D15: =SUMIF(Recipes!$A:$A,$A15,Recipes!$F:$F) | E15: =C15-D15 | F15: =IF(C15=0,"",D15/C15) | G15: =IF(C15=0,"",E15/C15)
A16: Arepa Queen | B16: Arepas | C16: 11.99 | D16: =SUMIF(Recipes!$A:$A,$A16,Recipes!$F:$F) | E16: =C16-D16 | F16: =IF(C16=0,"",D16/C16) | G16: =IF(C16=0,"",E16/C16)
A17: Cachapas | B17: Mains | C17: 16.99 | D17: =SUMIF(Recipes!$A:$A,$A17,Recipes!$F:$F) | E17: =C17-D17 | F17: =IF(C17=0,"",D17/C17) | G17: =IF(C17=0,"",E17/C17) | H17: Verify cachapas per pack on Ingredient Prices sheet
A18: Patacon (Original) | B18: Mains | C18: 19.95 | D18: =SUMIF(Recipes!$A:$A,$A18,Recipes!$F:$F) | E18: =C18-D18 | F18: =IF(C18=0,"",D18/C18) | G18: =IF(C18=0,"",E18/C18)
A19: Patacon (Vegetarian) | B19: Mains | C19: 15.99 | D19: =SUMIF(Recipes!$A:$A,$A19,Recipes!$F:$F) | E19: =C19-D19 | F19: =IF(C19=0,"",D19/C19) | G19: =IF(C19=0,"",E19/C19)
A20: Passion Fruit (20 oz) | B20: Drinks | C20: 4.75 | D20: =SUMIF(Recipes!$A:$A,$A20,Recipes!$F:$F) | E20: =C20-D20 | F20: =IF(C20=0,"",D20/C20) | G20: =IF(C20=0,"",E20/C20)
A21: Pineapple Juice (20 oz) | B21: Drinks | C21: 4.75 | D21: =SUMIF(Recipes!$A:$A,$A21,Recipes!$F:$F) | E21: =C21-D21 | F21: =IF(C21=0,"",D21/C21) | G21: =IF(C21=0,"",E21/C21)
A22: Papelon con Limon (20 oz) | B22: Drinks | C22: 4.75 | D22: =SUMIF(Recipes!$A:$A,$A22,Recipes!$F:$F) | E22: =C22-D22 | F22: =IF(C22=0,"",D22/C22) | G22: =IF(C22=0,"",E22/C22)
A23: Malta Polar (12 oz) | B23: Drinks | C23: 4.25 | D23: =SUMIF(Recipes!$A:$A,$A23,Recipes!$F:$F) | E23: =C23-D23 | F23: =IF(C23=0,"",D23/C23) | G23: =IF(C23=0,"",E23/C23) | H23: Cost is an estimate - no recent invoice
A24: Frescolita (12 oz) | B24: Drinks | C24: 4 | D24: =SUMIF(Recipes!$A:$A,$A24,Recipes!$F:$F) | E24: =C24-D24 | F24: =IF(C24=0,"",D24/C24) | G24: =IF(C24=0,"",E24/C24)
A25: Cri-Cri | B25: Candy | C25: 1.75 | D25: =SUMIF(Recipes!$A:$A,$A25,Recipes!$F:$F) | E25: =C25-D25 | F25: =IF(C25=0,"",D25/C25) | G25: =IF(C25=0,"",E25/C25)
A26: Pirucream | B26: Candy | C26: 15 | D26: =SUMIF(Recipes!$A:$A,$A26,Recipes!$F:$F) | E26: =C26-D26 | F26: =IF(C26=0,"",D26/C26) | G26: =IF(C26=0,"",E26/C26)
A27: Cocosette | B27: Candy | C27: 2 | D27: =SUMIF(Recipes!$A:$A,$A27,Recipes!$F:$F) | E27: =C27-D27 | F27: =IF(C27=0,"",D27/C27) | G27: =IF(C27=0,"",E27/C27)
A28: Samba (Strawberry) | B28: Candy | C28: 2 | D28: =SUMIF(Recipes!$A:$A,$A28,Recipes!$F:$F) | E28: =C28-D28 | F28: =IF(C28=0,"",D28/C28) | G28: =IF(C28=0,"",E28/C28)
A29: Carré (Savoy Hazelnut Milk Chocolate) | B29: Candy | C29: 3.75 | D29: =SUMIF(Recipes!$A:$A,$A29,Recipes!$F:$F) | E29: =C29-D29 | F29: =IF(C29=0,"",D29/C29) | G29: =IF(C29=0,"",E29/C29) | H29: Cost is an estimate - no recent invoice
A30: Savoy - Chocolate de Leche | B30: Candy | C30: 1.75 | D30: =SUMIF(Recipes!$A:$A,$A30,Recipes!$F:$F) | E30: =C30-D30 | F30: =IF(C30=0,"",D30/C30) | G30: =IF(C30=0,"",E30/C30)
A31: Galak - White Chocolate | B31: Candy | C31: 1.75 | D31: =SUMIF(Recipes!$A:$A,$A31,Recipes!$F:$F) | E31: =C31-D31 | F31: =IF(C31=0,"",D31/C31) | G31: =IF(C31=0,"",E31/C31)

Sheet Recipes
A1: Recipes - DRAFT portions, please correct
A2: Qty unit must match the ingredient's unit on the Ingredient Prices sheet. Edit Qty (col C) to your real serving sizes; costs update automatically. Add rows freely - keep the menu item name identical to the Menu Profitability sheet.
A4: Menu Item | B4: Ingredient | C4: Qty | D4: Unit | E4: Unit Cost | F4: Line Cost | G4: Notes
A5: Yucca Fries (7 units) | B5: Yuca fries frozen | C5: 8 | D5: oz | E5: =IFERROR(VLOOKUP($B5,'Ingredient Prices'!$A:$I,9,FALSE),0) | F5: =IF(ISNUMBER(E5),C5*E5,0) | G5: DRAFT: ~8 oz per order
A6: Yucca Fries (7 units) | B6: Frying shortening (canola liquid) | C6: 1.5 | D6: oz | E6: =IFERROR(VLOOKUP($B6,'Ingredient Prices'!$A:$I,9,FALSE),0) | F6: =IF(ISNUMBER(E6),C6*E6,0) | G6: DRAFT: oil absorbed in frying
A7: Yucca Fries (7 units) | B7: Guasacaca sauce (house-made) | C7: 1.5 | D7: fl oz | E7: =IFERROR(VLOOKUP($B7,'Ingredient Prices'!$A:$I,9,FALSE),0) | F7: =IF(ISNUMBER(E7),C7*E7,0) | G7: DRAFT: dipping sauce
A8: Yucca Fries (7 units) | B8: To-go container/wrap | C8: 1 | D8: each | E8: =IFERROR(VLOOKUP($B8,'Ingredient Prices'!$A:$I,9,FALSE),0) | F8: =IF(ISNUMBER(E8),C8*E8,0)
A9: Plantains and Cheese (7 units) | B9: Sweet plantain IQF | C9: 8 | D9: oz | E9: =IFERROR(VLOOKUP($B9,'Ingredient Prices'!$A:$I,9,FALSE),0) | F9: =IF(ISNUMBER(E9),C9*E9,0) | G9: DRAFT: ~8 oz per order
A10: Plantains and Cheese (7 units) | B10: Queso de Mano | C10: 1.5 | D10: oz | E10: =IFERROR(VLOOKUP($B10,'Ingredient Prices'!$A:$I,9,FALSE),0) | F10: =IF(ISNUMBER(E10),C10*E10,0) | G10: DRAFT: white cheese topping
A11: Plantains and Cheese (7 units) | B11: Frying shortening (canola liquid) | C11: 1 | D11: oz | E11: =IFERROR(VLOOKUP($B11,'Ingredient Prices'!$A:$I,9,FALSE),0) | F11: =IF(ISNUMBER(E11),C11*E11,0) | G11: DRAFT
A12: Plantains and Cheese (7 units) | B12: To-go container/wrap | C12: 1 | D12: each | E12: =IFERROR(VLOOKUP($B12,'Ingredient Prices'!$A:$I,9,FALSE),0) | F12: =IF(ISNUMBER(E12),C12*E12,0)
A13: Tequeños (5 units) | B13: Tequenos (frozen) | C13: 5 | D13: each | E13: =IFERROR(VLOOKUP($B13,'Ingredient Prices'!$A:$I,9,FALSE),0) | F13: =IF(ISNUMBER(E13),C13*E13,0) | G13: 5 units per order
A14: Tequeños (5 units) | B14: Frying shortening (canola liquid) | C14: 1 | D14: oz | E14: =IFERROR(VLOOKUP($B14,'Ingredient Prices'!$A:$I,9,FALSE),0) | F14: =IF(ISNUMBER(E14),C14*E14,0) | G14: DRAFT: air fried - may be less
A15: Tequeños (5 units) | B15: Guasacaca sauce (house-made) | C15: 1.5 | D15: fl oz | E15: =IFERROR(VLOOKUP($B15,'Ingredient Prices'!$A:$I,9,FALSE),0) | F15: =IF(ISNUMBER(E15),C15*E15,0) | G15: DRAFT: dipping sauce
A16: Tequeños (5 units) | B16: To-go container/wrap | C16: 1 | D16: each | E16: =IFERROR(VLOOKUP($B16,'Ingredient Prices'!$A:$I,9,FALSE),0) | F16: =IF(ISNUMBER(E16),C16*E16,0)
A17: Empanadas | B17: Harina P.A.N. (cornmeal) | C17: 2.5 | D17: oz | E17: =IFERROR(VLOOKUP($B17,'Ingredient Prices'!$A:$I,9,FALSE),0) | F17: =IF(ISNUMBER(E17),C17*E17,0) | G17: DRAFT: dough per empanada
A18: Empanadas | B18: Beef rib lifter meat (raw) | C18: 1.5 | D18: oz | E18: =IFERROR(VLOOKUP($B18,'Ingredient Prices'!$A:$I,9,FALSE),0) | F18: =IF(ISNUMBER(E18),C18*E18,0) | G18: DRAFT: avg filling (beef/chicken/cheese)
A19: Empanadas | B19: Frying shortening (canola liquid) | C19: 1.5 | D19: oz | E19: =IFERROR(VLOOKUP($B19,'Ingredient Prices'!$A:$I,9,FALSE),0) | F19: =IF(ISNUMBER(E19),C19*E19,0) | G19: DRAFT
A20: Empanadas | B20: To-go container/wrap | C20: 0.5 | D20: each | E20: =IFERROR(VLOOKUP($B20,'Ingredient Prices'!$A:$I,9,FALSE),0) | F20: =IF(ISNUMBER(E20),C20*E20,0) | G20: DRAFT: shared packaging
A21: Pastelitos | B21: Harina P.A.N. (cornmeal) | C21: 2.5 | D21: oz | E21: =IFERROR(VLOOKUP($B21,'Ingredient Prices'!$A:$I,9,FALSE),0) | F21: =IF(ISNUMBER(E21),C21*E21,0) | G21: DRAFT: dough
A22: Pastelitos | B22: Ham | C22: 1 | D22: oz | E22: =IFERROR(VLOOKUP($B22,'Ingredient Prices'!$A:$I,9,FALSE),0) | F22: =IF(ISNUMBER(E22),C22*E22,0) | G22: DRAFT: ham & cheese filling
A23: Pastelitos | B23: White cheese (mozzarella/llanero) | C23: 1 | D23: oz | E23: =IFERROR(VLOOKUP($B23,'Ingredient Prices'!$A:$I,9,FALSE),0) | F23: =IF(ISNUMBER(E23),C23*E23,0) | G23: DRAFT
A24: Pastelitos | B24: Frying shortening (canola liquid) | C24: 1.5 | D24: oz | E24: =IFERROR(VLOOKUP($B24,'Ingredient Prices'!$A:$I,9,FALSE),0) | F24: =IF(ISNUMBER(E24),C24*E24,0) | G24: DRAFT
A25: Pastelitos | B25: To-go container/wrap | C25: 0.5 | D25: each | E25: =IFERROR(VLOOKUP($B25,'Ingredient Prices'!$A:$I,9,FALSE),0) | F25: =IF(ISNUMBER(E25),C25*E25,0) | G25: DRAFT: shared packaging
A26: Arepa Cheese | B26: Harina P.A.N. (cornmeal) | C26: 3 | D26: oz | E26: =IFERROR(VLOOKUP($B26,'Ingredient Prices'!$A:$I,9,FALSE),0) | F26: =IF(ISNUMBER(E26),C26*E26,0) | G26: DRAFT: arepa shell
A27: Arepa Cheese | B27: Queso de Mano | C27: 2.5 | D27: oz | E27: =IFERROR(VLOOKUP($B27,'Ingredient Prices'!$A:$I,9,FALSE),0) | F27: =IF(ISNUMBER(E27),C27*E27,0) | G27: DRAFT: thick melted cheese
A28: Arepa Cheese | B28: Butter | C28: 0.3 | D28: oz | E28: =IFERROR(VLOOKUP($B28,'Ingredient Prices'!$A:$I,9,FALSE),0) | F28: =IF(ISNUMBER(E28),C28*E28,0) | G28: DRAFT
A29: Arepa Cheese | B29: Guasacaca sauce (house-made) | C29: 1 | D29: fl oz | E29: =IFERROR(VLOOKUP($B29,'Ingredient Prices'!$A:$I,9,FALSE),0) | F29: =IF(ISNUMBER(E29),C29*E29,0) | G29: DRAFT
A30: Arepa Cheese | B30: To-go container/wrap | C30: 1 | D30: each | E30: =IFERROR(VLOOKUP($B30,'Ingredient Prices'!$A:$I,9,FALSE),0) | F30: =IF(ISNUMBER(E30),C30*E30,0)
A31: Arepa Domino | B31: Harina P.A.N. (cornmeal) | C31: 3 | D31: oz | E31: =IFERROR(VLOOKUP($B31,'Ingredient Prices'!$A:$I,9,FALSE),0) | F31: =IF(ISNUMBER(E31),C31*E31,0) | G31: DRAFT: arepa shell
A32: Arepa Domino | B32: Black beans (cooked) | C32: 3 | D32: oz | E32: =IFERROR(VLOOKUP($B32,'Ingredient Prices'!$A:$I,9,FALSE),0) | F32: =IF(ISNUMBER(E32),C32*E32,0) | G32: DRAFT
A33: Arepa Domino | B33: Cotija cheese | C33: 1 | D33: oz | E33: =IFERROR(VLOOKUP($B33,'Ingredient Prices'!$A:$I,9,FALSE),0) | F33: =IF(ISNUMBER(E33),C33*E33,0) | G33: DRAFT
A34: Arepa Domino | B34: Guasacaca sauce (house-made) | C34: 1 | D34: fl oz | E34: =IFERROR(VLOOKUP($B34,'Ingredient Prices'!$A:$I,9,FALSE),0) | F34: =IF(ISNUMBER(E34),C34*E34,0) | G34: DRAFT
A35: Arepa Domino | B35: To-go container/wrap | C35: 1 | D35: each | E35: =IFERROR(VLOOKUP($B35,'Ingredient Prices'!$A:$I,9,FALSE),0) | F35: =IF(ISNUMBER(E35),C35*E35,0)
A36: Arepa Chicken | B36: Harina P.A.N. (cornmeal) | C36: 3 | D36: oz | E36: =IFERROR(VLOOKUP($B36,'Ingredient Prices'!$A:$I,9,FALSE),0) | F36: =IF(ISNUMBER(E36),C36*E36,0) | G36: DRAFT: arepa shell
A37: Arepa Chicken | B37: Chicken breast jumbo (raw) | C37: 4.5 | D37: oz | E37: =IFERROR(VLOOKUP($B37,'Ingredient Prices'!$A:$I,9,FALSE),0) | F37: =IF(ISNUMBER(E37),C37*E37,0) | G37: DRAFT: raw wt for ~3.5 oz cooked shredded
A38: Arepa Chicken | B38: Sweet plantain IQF | C38: 2 | D38: oz | E38: =IFERROR(VLOOKUP($B38,'Ingredient Prices'!$A:$I,9,FALSE),0) | F38: =IF(ISNUMBER(E38),C38*E38,0) | G38: DRAFT
A39: Arepa Chicken | B39: Cheddar shredded | C39: 1 | D39: oz | E39: =IFERROR(VLOOKUP($B39,'Ingredient Prices'!$A:$I,9,FALSE),0) | F39: =IF(ISNUMBER(E39),C39*E39,0) | G39: DRAFT
A40: Arepa Chicken | B40: Guasacaca sauce (house-made) | C40: 1 | D40: fl oz | E40: =IFERROR(VLOOKUP($B40,'Ingredient Prices'!$A:$I,9,FALSE),0) | F40: =IF(ISNUMBER(E40),C40*E40,0) | G40: DRAFT
A41: Arepa Chicken | B41: To-go container/wrap | C41: 1 | D41: each | E41: =IFERROR(VLOOKUP($B41,'Ingredient Prices'!$A:$I,9,FALSE),0) | F41: =IF(ISNUMBER(E41),C41*E41,0)
...

Sheet Ingredient Prices
A1: Ingredient Prices - from supplier invoices (Jun 12 - Jul 9, 2026)
A2: Unit Cost = Pack Price / Yield Qty. Yellow = invoice price but pack size assumed (verify). Orange = no recent invoice, market ESTIMATE (replace). Dark orange = price unreadable on scan (enter it).
A4: Ingredient | B4: Vendor | C4: Last Invoice | D4: Invoice # | E4: Pack | F4: Pack Price | G4: Yield Qty | H4: Unit | I4: Unit Cost | J4: Status | K4: Notes
A5: Tequenos (frozen) | B5: Latin Market Mana | C5: 2026-07-07 | D5: SVFPDYSHPK2NC | E5: 160 units/case | F5: 87.75 | G5: 160 | H5: each | I5: =IF(AND(ISNUMBER(F5),ISNUMBER(G5),G5>0),F5/G5,"") | J5: INVOICE
A6: Cachapa pack (Palmita, w/ queso) | B6: Latin Market Mana | C6: 2026-07-07 | D6: SVFPDYSHPK2NC | E6: 1 pack | F6: 13.99 | G6: 1 | H6: pack | I6: =IF(AND(ISNUMBER(F6),ISNUMBER(G6),G6>0),F6/G6,"") | J6: CHECK | K6: How many cachapas per pack? Update yield qty.
A7: Queso de Mano | B7: Latin Market Mana | C7: 2026-07-07 | D7: SVFPDYSHPK2NC | E7: 26 oz wheel | F7: 11 | G7: 26 | H7: oz | I7: =IF(AND(ISNUMBER(F7),ISNUMBER(G7),G7>0),F7/G7,"") | J7: INVOICE
A8: Nata (crema) | B8: Latin Market Mana | C8: 2026-07-07 | D8: SVFPDYSHPK2NC | E8: 32 lb tub | F8: 116 | G8: 512 | H8: oz | I8: =IF(AND(ISNUMBER(F8),ISNUMBER(G8),G8>0),F8/G8,"") | J8: INVOICE
A9: Concentrado de Pina | B9: Latin Market Mana | C9: 2026-07-07 | D9: SVFPDYSHPK2NC | E9: 1 gal | F9: 15.39 | G9: 128 | H9: fl oz | I9: =IF(AND(ISNUMBER(F9),ISNUMBER(G9),G9>0),F9/G9,"") | J9: INVOICE
A10: Concentrado de Parchita | B10: Latin Market Mana | C10: 2026-07-04 | D10: 0RJ9HAABW6KF8 | E10: 1 gal | F10: 15.39 | G10: 128 | H10: fl oz | I10: =IF(AND(ISNUMBER(F10),ISNUMBER(G10),G10>0),F10/G10,"") | J10: INVOICE
A11: Frescolita (12 oz can) | B11: Latin Market Mana | C11: 2026-06-23 | D11: PSEKS3P317GJR | E11: 24-can case | F11: 23 | G11: 24 | H11: each | I11: =IF(AND(ISNUMBER(F11),ISNUMBER(G11),G11>0),F11/G11,"") | J11: INVOICE
A12: Cocosette | B12: Latin Market Mana | C12: 2026-06-12 | D12: VA375MKQ3HGWG | E12: 18 x 50 g | F12: 14.73 | G12: 18 | H12: each | I12: =IF(AND(ISNUMBER(F12),ISNUMBER(G12),G12>0),F12/G12,"") | J12: INVOICE
A13: Samba (Strawberry) | B13: Latin Market Mana | C13: 2026-06-12 | D13: VA375MKQ3HGWG | E13: 20 x 32 g | F13: 18.81 | G13: 20 | H13: each | I13: =IF(AND(ISNUMBER(F13),ISNUMBER(G13),G13>0),F13/G13,"") | J13: INVOICE
A14: Cri-Cri | B14: Latin Market Mana | C14: 2026-06-12 | D14: VA375MKQ3HGWG | E14: 12 x 27 g | F14: 11.93 | G14: 12 | H14: each | I14: =IF(AND(ISNUMBER(F14),ISNUMBER(G14),G14>0),F14/G14,"") | J14: INVOICE
A15: Savoy Chocolate de Leche | B15: Latin Market Mana | C15: 2026-06-12 | D15: VA375MKQ3HGWG | E15: 12 x 30 g | F15: 13.5 | G15: 12 | H15: each | I15: =IF(AND(ISNUMBER(F15),ISNUMBER(G15),G15>0),F15/G15,"") | J15: INVOICE
A16: Galak White Chocolate | B16: Latin Market Mana | C16: 2026-06-12 | D16: VA375MKQ3HGWG | E16: 12 x 30 g | F16: 11.93 | G16: 12 | H16: each | I16: =IF(AND(ISNUMBER(F16),ISNUMBER(G16),G16>0),F16/G16,"") | J16: INVOICE
A17: Pirucream (300 g can) | B17: Latin Market Mana | C17: 2026-06-12 | D17: VA375MKQ3HGWG | E17: 300 g can | F17: 6.97 | G17: 1 | H17: each | I17: =IF(AND(ISNUMBER(F17),ISNUMBER(G17),G17>0),F17/G17,"") | J17: INVOICE
A18: Beef rib lifter meat (raw) | B18: US Foods | C18: 2026-07-09 | D18: 3190-0146 | E18: catch weight, $/lb | F18: 6.23 | G18: 16 | H18: oz | I18: =IF(AND(ISNUMBER(F18),ISNUMBER(G18),G18>0),F18/G18,"") | J18: INVOICE | K18: 162.2 lb delivered on last invoice
A19: Chicken breast jumbo (raw) | B19: US Foods | C19: 2026-07-09 | D19: 3190-0146 | E19: 4/10 lb case | F19: 107.34 | G19: 640 | H19: oz | I19: =IF(AND(ISNUMBER(F19),ISNUMBER(G19),G19>0),F19/G19,"") | J19: CHECK | K19: Extended price partly unreadable on scan - verify $107.34/case
A20: Cheddar shredded | B20: US Foods | C20: 2026-07-09 | D20: 3190-0146 | E20: 4/5 lb case | F20: 139.18 | G20: 320 | H20: oz | I20: =IF(AND(ISNUMBER(F20),ISNUMBER(G20),G20>0),F20/G20,"") | J20: CHECK | K20: Extended price partly unreadable on scan - verify $139.18/case
A21: Frying shortening (canola liquid) | B21: US Foods | C21: 2026-07-09 | D21: 3190-0146 | E21: 35 lb case | F21: 42.04 | G21: 560 | H21: oz | I21: =IF(AND(ISNUMBER(F21),ISNUMBER(G21),G21>0),F21/G21,"") | J21: INVOICE
A22: Red bell pepper (morron) | B22: Mission & Vegetable | C22: 2026-07-09 | D22: 41123 | E22: case (~25 lb assumed) | F22: 38.75 | G22: 400 | H22: oz | I22: =IF(AND(ISNUMBER(F22),ISNUMBER(G22),G22>0),F22/G22,"") | J22: CHECK | K22: Case weight not on invoice - assumed 25 lb
A23: Yellow onion | B23: Mission & Vegetable | C23: 2026-07-09 | D23: 41123 | E23: sack (~50 lb assumed) | F23: 25.75 | G23: 800 | H23: oz | I23: =IF(AND(ISNUMBER(F23),ISNUMBER(G23),G23>0),F23/G23,"") | J23: CHECK | K23: Sack weight not on invoice - assumed 50 lb
A24: Apio (celery) | B24: Mission & Vegetable | C24: 2026-07-09 | D24: 41123 | E24: case (~28 lb assumed) | F24: 27.75 | G24: 448 | H24: oz | I24: =IF(AND(ISNUMBER(F24),ISNUMBER(G24),G24>0),F24/G24,"") | J24: CHECK | K24: Case weight not on invoice - assumed 28 lb
A25: Avocado (#48 case) | B25: Mission & Vegetable | C25: 2026-07-09 | D25: 41123 | E25: 48-count case | F25: 46.75 | G25: 48 | H25: each | I25: =IF(AND(ISNUMBER(F25),ISNUMBER(G25),G25>0),F25/G25,"") | J25: INVOICE
A26: Habanero | B26: Mission & Vegetable | C26: 2026-06-25 | D26: 40457 | E26: case (~8 lb assumed) | F26: 43.75 | G26: 128 | H26: oz | I26: =IF(AND(ISNUMBER(F26),ISNUMBER(G26),G26>0),F26/G26,"") | J26: CHECK | K26: Case weight not on invoice - assumed 8 lb
A27: Mayonnaise | B27: Restaurant Depot | C27: 2026-07-06 | D27: 20544606249422176 | E27: 4 x 1 gal | F27: 44.55 | G27: 512 | H27: fl oz | I27: =IF(AND(ISNUMBER(F27),ISNUMBER(G27),G27>0),F27/G27,"") | J27: INVOICE
A28: Black beans (cooked) | B28: Restaurant Depot | C28: 2026-07-06 | D28: 20544606249422176 | E28: 25 lb dry bag | F28: 13.33 | G28: 880 | H28: oz | I28: =IF(AND(ISNUMBER(F28),ISNUMBER(G28),G28>0),F28/G28,"") | J28: CHECK | K28: 25 lb dry x ~2.2 cooked yield = 55 lb cooked (880 oz)
A29: Seasoning salt | B29: Restaurant Depot | C29: 2026-07-06 | D29: 20544606249422176 | E29: 10 lb jar (substituted) | F29: 67.44 | G29: 160 | H29: oz | I29: =IF(AND(ISNUMBER(F29),ISNUMBER(G29),G29>0),F29/G29,"") | J29: CHECK | K29: 20 lb was substituted w/ 10 lb jar - verify charge
A30: Canola salad oil | B30: Restaurant Depot | C30: 2026-07-06 | D30: 20544606249422176 | E30: 35 lb | F30: 41.82 | G30: 560 | H30: oz | I30: =IF(AND(ISNUMBER(F30),ISNUMBER(G30),G30>0),F30/G30,"") | J30: INVOICE
A31: Peeled garlic | B31: Restaurant Depot | C31: 2026-07-06 | D31: 20544606249422176 | E31: jar (~5 lb assumed) | F31: 15.95 | G31: 80 | H31: oz | I31: =IF(AND(ISNUMBER(F31),ISNUMBER(G31),G31>0),F31/G31,"") | J31: CHECK | K31: Jar size not on receipt - assumed 5 lb
A32: Yuca fries frozen | B32: US Foods (?) | C32: 2026-06-29 | D32: ? | E32: 20 x 1 lb | G32: 320 | H32: oz | I32: =IF(AND(ISNUMBER(F32),ISNUMBER(G32),G32>0),F32/G32,"") | J32: PRICE NEEDED | K32: 07-03 invoice scan unreadable - ENTER PACK PRICE
A33: Sweet plantain IQF | B33: US Foods (?) | C33: 2026-06-29 | D33: ? | E33: 4 x 6 lb | G33: 384 | H33: oz | I33: =IF(AND(ISNUMBER(F33),ISNUMBER(G33),G33>0),F33/G33,"") | J33: PRICE NEEDED | K33: 07-03 invoice scan unreadable - ENTER PACK PRICE
A34: Harina P.A.N. (cornmeal) | B34: - | C34: - | D34: - | E34: 50 lb (ESTIMATE) | F34: 45 | G34: 800 | H34: oz | I34: =IF(AND(ISNUMBER(F34),ISNUMBER(G34),G34>0),F34/G34,"") | J34: ESTIMATE | K34: No invoice in last 30 days - replace with real price
A35: White cheese (mozzarella/llanero) | B35: - | C35: - | D35: - | E35: per lb (ESTIMATE) | F35: 3.25 | G35: 16 | H35: oz | I35: =IF(AND(ISNUMBER(F35),ISNUMBER(G35),G35>0),F35/G35,"") | J35: ESTIMATE | K35: Replace with real price
A36: Cotija cheese | B36: - | C36: - | D36: - | E36: per lb (ESTIMATE) | F36: 4.5 | G36: 16 | H36: oz | I36: =IF(AND(ISNUMBER(F36),ISNUMBER(G36),G36>0),F36/G36,"") | J36: ESTIMATE | K36: Replace with real price
A37: Green plantain | B37: - | C37: - | D37: - | E37: each (ESTIMATE) | F37: 0.6 | G37: 1 | H37: each | I37: =IF(AND(ISNUMBER(F37),ISNUMBER(G37),G37>0),F37/G37,"") | J37: ESTIMATE | K37: Replace with real price
A38: Lettuce | B38: - | C38: - | D38: - | E38: head (ESTIMATE) | F38: 2.5 | G38: 1 | H38: each | I38: =IF(AND(ISNUMBER(F38),ISNUMBER(G38),G38>0),F38/G38,"") | J38: ESTIMATE | K38: Replace with real price
A39: Tomato | B39: - | C39: - | D39: - | E39: per lb (ESTIMATE) | F39: 1.8 | G39: 16 | H39: oz | I39: =IF(AND(ISNUMBER(F39),ISNUMBER(G39),G39>0),F39/G39,"") | J39: ESTIMATE | K39: Replace with real price
A40: Cabbage | B40: - | C40: - | D40: - | E40: per lb (ESTIMATE) | F40: 0.9 | G40: 16 | H40: oz | I40: =IF(AND(ISNUMBER(F40),ISNUMBER(G40),G40>0),F40/G40,"") | J40: ESTIMATE | K40: Replace with real price
A41: Carrot | B41: - | C41: - | D41: - | E41: per lb (ESTIMATE) | F41: 0.8 | G41: 16 | H41: oz | I41: =IF(AND(ISNUMBER(F41),ISNUMBER(G41),G41>0),F41/G41,"") | J41: ESTIMATE | K41: Replace with real price
...

Sheet Invoice Log
A1: Raw invoice line items (reference)
A3: Vendor | B3: Invoice Date | C3: Invoice # | D3: Description | E3: Qty | F3: Pack/Size | G3: Unit Price | H3: Line Total
A4: US Foods, Inc. | B4: 2026-07-09 | C4: 3190 0146? | D4: SHORTENING, FRYG CNOLA LIQ CLR (HARVEST VAL) | E4: 2 | F4: 35 LB CS | G4: 42.04 | H4: 84.08
A5: US Foods, Inc. | B5: 2026-07-09 | C5: 3190 0146? | D5: PEPPER, BELL RED #2 GRD 22-28 (PACKER) | E5: 1? | F5: 1.1 BU CS | H5: 85.07? (or 84.07)
A6: US Foods, Inc. | B6: 2026-07-09 | C6: 3190 0146? | D6: CHICKEN, BRST DBL RND JMB (PATUXENT) | F6: 4/10 LB CS | H6: 107.34? (or 187.34)
A7: US Foods, Inc. | B7: 2026-07-09 | C7: 3190 0146? | D7: CHEESE, CHEDR MILD SHRD FTHR (GLNVW FRMS) | F7: 4/5 LB CS | H7: 139.18?
A8: US Foods, Inc. | B8: 2026-07-09 | C8: 3190 0146? | D8: BEEF, RIB LIFTER MEAT CAB RAW (PACKER) - catch weight 162.20 LBS | E8: 2 | F8: 75 LBA CS (CS1: 82.00 LBS, CS2: 80.20 LBS) | G8: 6.23 | H8: 1010.51
A9: US Foods, Inc. | B9: 2026-07-09 | C9: 3190 0146? | D9: Fuel Surcharge | E9: 1 | G9: 9 | H9: 9
A10: US Foods, Inc. | B10: 2026-07-09 | C10: 3190 0146? | D10: CO RETAIL DEL FEE | E10: 1 | G10: 0.31 | H10: 0.31
A11: Mission & Vegetable LLC | B11: 2026-07-09 | C11: 41123 | D11: morron rojo | E11: 1 | G11: 38.75 | H11: 38.75
A12: Mission & Vegetable LLC | B12: 2026-07-09 | C12: 41123 | D12: Cebolla amarilla COLOSO | E12: 1 | G12: 25.75 | H12: 25.75
A13: Mission & Vegetable LLC | B13: 2026-07-09 | C13: 41123 | D13: Apio | E13: 1 | G13: 27.75 | H13: 27.75
A14: Mission & Vegetable LLC | B14: 2026-07-09 | C14: 41123 | D14: aguacte 48 verde #1 (SOLO #48 y VERDE VERDE OJOOOO) | E14: 3 | F14: #48 count case | G14: 46.75 | H14: 140.25
A15: Latin Market Mana (MANA Mayorista) | B15: 2026-07-07 | C15: SVFPDYSHPK2NC? | D15: Cachapas Queso Palmita | E15: 10 | F15: Unit | G15: 13.99 | H15: 139.9
A16: Latin Market Mana (MANA Mayorista) | B16: 2026-07-07 | C16: SVFPDYSHPK2NC? | D16: Queso de Mano 26 Oz | E16: 15 | F16: Unit (26 OZ) | G16: 11 | H16: 165
A17: Latin Market Mana (MANA Mayorista) | B17: 2026-07-07 | C17: SVFPDYSHPK2NC? | D17: Nata Mana 32 Libras | E17: 1 | F17: 32 LB | G17: 116 | H17: 116
A18: Latin Market Mana (MANA Mayorista) | B18: 2026-07-07 | C18: SVFPDYSHPK2NC? | D18: Concentrado pina | E18: 6 | F18: Unit | G18: 15.39 | H18: 92.34
A19: Latin Market Mana (MANA Mayorista) | B19: 2026-07-07 | C19: SVFPDYSHPK2NC? | D19: Tequenos Mana 160 Unidades | E19: 2 | F19: 160 unidades | G19: 87.75 | H19: 175.5
A20: Clean Green | B20: 2026-07-07 | C20: 300236676 | D20: BAR TOWEL (9930) - Rent | E20: 150 | G20: 0.17 | H20: 25.5
A21: Clean Green | B21: 2026-07-07 | C21: 300236676 | D21: BAR TOWEL (9930) - MMP | E21: 6 | G21: 1.11 | H21: 6.66
A22: Clean Green | B22: 2026-07-07 | C22: 300236676 | D22: Delivery Charge | E22: 1 | G22: 0.31 | H22: 0.31
A23: Clean Green | B23: 2026-07-07 | C23: 300236676 | D23: Delivery Charge | E23: 1 | G23: 6.53 | H23: 6.53
A24: Clean Green | B24: 2026-07-07 | C24: 300236676 | D24: CO Tax (CO's) | E24: 3 | H24: 1.12
A25: Clean Green | B25: 2026-07-07 | C25: 300236676 | D25: EDGEWATER Tax (CO32) | E25: 3 | H25: 1.78
A26: Clean Green | B26: 2026-07-07 | C26: 300236676 | D26: JEFFERSON COUNTY Tax (COC2) | E26: 3 | H26: 0.19
A27: Restaurant Depot (Denver, 1740 W 13th Ave) | B27: 2026-07-06 | C27: 20544606249422176 | D27: Chef's Quality - Mayonnaise - 4 gallons | E27: 3 | F27: 4 GAL | G27: 44.55 | H27: 133.65
A28: Restaurant Depot (Denver, 1740 W 13th Ave) | B28: 2026-07-06 | C28: 20544606249422176 | D28: Chef's Quality - Black Beans - 25 lbs | E28: 2 | F28: 25 LB | G28: 13.33 | H28: 26.66
A29: Restaurant Depot (Denver, 1740 W 13th Ave) | B29: 2026-07-06 | C29: 20544606249422176 | D29: Chef's Quality - Seasoning Salt - 20 lbs (substituted: Seasoning Salt 10 lb Jar) | E29: 1 | F29: 20 LB | G29: 67.44 | H29: 67.44
A30: Restaurant Depot (Denver, 1740 W 13th Ave) | B30: 2026-07-06 | C30: 20544606249422176 | D30: Chef's Quality - Canola Frying Oil for Heavy Duty Frying - 35 lbs (substituted: 100% Canola Salad Oil 35 lbs) | E30: 2 | F30: 35 LB | G30: 41.82 | H30: 83.64
A31: Restaurant Depot (Denver, 1740 W 13th Ave) | B31: 2026-07-06 | C31: 20544606249422176 | D31: Peeled Garlic | E31: 1 | F31: Unit | G31: 15.95 | H31: 15.95
A32: Unknown (broadline frozen-foods distributor)? | B32: 06/29/26? | C32: ? | D32: YUCA, FF CKD BAG FZN (verbatim OCR: 'YWCA, FF CKD BAG FZN 20/1 1_B') | E32: ? | F32: 20/1 LB | G32: ? | H32: ?
A33: Unknown (broadline frozen-foods distributor)? | B33: 06/29/26? | C33: ? | D33: PLANTAIN, S? ... IQF (verbatim OCR: '"ANTAXN, Si." "T N" "!] IQF4/d LB') — likely PLANTAIN, SWEET IQF 4/6 LB? | E33: ? | F33: 4/6 LB? | G33: ? | H33: ?
A34: Prudential Overall Supply (CLEANGREEN) | B34: 06/30/2026 | C34: 300236226 | D34: 9930 BAR TOWEL Rent | E34: 150? | F34: each (rental) | G34: 0.171 | H34: 25.5
A35: Prudential Overall Supply (CLEANGREEN) | B35: 06/30/2026 | C35: 300236226 | D35: 9930 BAR TOWEL MMP | E35: 6 | F35: each | G35: 1.11 | H35: 6.66
A36: Prudential Overall Supply (CLEANGREEN) | B36: 06/30/2026 | C36: 300236226 | D36: Delivery Charge | E36: 1 | G36: 0.28 | H36: 0.28
A37: Prudential Overall Supply (CLEANGREEN) | B37: 06/30/2026 | C37: 300236226 | D37: Delivery Charge | E37: 1 | G37: 6.53 | H37: 6.53
A38: Latin Market Mana (Mayorista) | B38: 2026-07-01 | C38: GZS4NEZH3S33E | D38: Concentrado de pina 1 Galon | E38: 6 | F38: 1 Galon (Unit) | G38: 15.39 | H38: 92.34
A39: Latin Market Mana (Mayorista) | B39: 2026-07-01 | C39: GZS4NEZH3S33E | D39: Cachapas Queso Palmita | E39: 10 | F39: Unit | G39: 13.99 | H39: 139.9
A40: Latin Market Mana (Mayorista) | B40: 2026-07-01 | C40: GZS4NEZH3S33E | D40: Tequenos Mana 160 Unidades | E40: 4 | F40: 160 Unidades (Unit) | G40: 87.75 | H40: 351
A41: Latin Market Mana (Mayorista) | B41: 2026-07-04 | C41: 0RJ9HAABW6KF8 | D41: Concentrado de Parchita 1 Galon | E41: 20 | F41: 1 Galon (Unit) | G41: 15.39 | H41: 307.8
...

Sheet README
A1: Arepas House - Menu Profitability Workbook
A2: Generated 2026-07-11 by Claude from Square catalog + supplier invoices in Google Drive 'Claude Managed/Supplier Invoices'.
A4: HOW IT WORKS
A5: 1. 'Ingredient Prices' holds what you pay vendors, converted to a cost per oz / fl oz / each.
A6: 2. 'Recipes' lists what goes into each menu item. Line Cost = Qty x Unit Cost (looked up automatically).
A7: 3. 'Menu Profitability' sums each item's recipe lines and compares to the Square menu price.
A8: Food Cost % is color coded: green < 30%, yellow 30-40%, red > 40%.
A10: WHAT YOU NEED TO REVIEW (in priority order)
A11: A. Recipe portions (Recipes sheet, col C) are DRAFT estimates from the menu descriptions.
A12: Correct them to your real serving sizes - everything recalculates.
A13: B. Dark-orange rows on 'Ingredient Prices': yuca fries and sweet plantain prices were unreadable
A14: on the 07-03 invoice scan. Enter the pack price - until then Yucca Fries and Plantains & Cheese costs are understated.
... A24: - US Foods 07-09 scan was partly unreadable: chicken $107.34/case and cheddar $139.18/case are best readings - verify.
